Workbook

Sheet Sheet1

Sheet Sheet2

Sheet Sheet3

Sheet Summary
A1: Employee | B1: 02/02 | C1: 02/03 | D1: 02/04 | E1: 02/05 | F1: 02/06 | G1: 02/07 | H1: 02/09 | I1: 02/10 | J1: 02/11 | K1: 02/12 | L1: 02/13 | M1: 02/14 | N1: 02/15 | O1: 02/16 | P1: 02/17 | Q1: 02/18 | R1: 02/19 | S1: 02/20 | T1: 02/21 | U1: 02/22 | V1: 02/23 | W1: 02/24 | X1: 02/25 | Y1: 02/26 | Z1: 02/27 | AA1: 02/28 | AB1: MTD Utilization
A2: Albert Karson | C2: ='Albert Karson'!F24/'Albert Karson'!F26 | D2: ='Albert Karson'!G24/'Albert Karson'!G26 | E2: ='Albert Karson'!H24/'Albert Karson'!H26 | K2: ='Albert Karson'!N24/'Albert Karson'!N26 | P2: ='Albert Karson'!S24/'Albert Karson'!S26 | Q2: ='Albert Karson'!T24/'Albert Karson'!T26 | R2: ='Albert Karson'!U24/'Albert Karson'!U26 | S2: ='Albert Karson'!V24/'Albert Karson'!V26 | V2: ='Albert Karson'!Y24/'Albert Karson'!Y26 | W2: ='Albert Karson'!Z24/'Albert Karson'!Z26 | X2: ='Albert Karson'!AA24/'Albert Karson'!AA26 | Y2: ='Albert Karson'!AB24/'Albert Karson'!AB26 | Z2: ='Albert Karson'!AC24/'Albert Karson'!AC26 | AB2: ='Albert Karson'!AE24/'Albert Karson'!AE26
A3: Alice Raymond | B3: ='Alice Raymond'!E24/'Alice Raymond'!E26 | C3: ='Alice Raymond'!F24/'Alice Raymond'!F26 | D3: ='Alice Raymond'!G24/'Alice Raymond'!G26 | E3: ='Alice Raymond'!H24/'Alice Raymond'!H26 | F3: ='Alice Raymond'!I24/'Alice Raymond'!I26 | I3: ='Alice Raymond'!L24/'Alice Raymond'!L26 | J3: ='Alice Raymond'!M24/'Alice Raymond'!M26 | K3: ='Alice Raymond'!N24/'Alice Raymond'!N26 | L3: ='Alice Raymond'!O24/'Alice Raymond'!O26 | P3: ='Alice Raymond'!S24/'Alice Raymond'!S26 | Q3: ='Alice Raymond'!T24/'Alice Raymond'!T26 | R3: ='Alice Raymond'!U24/'Alice Raymond'!U26 | S3: ='Alice Raymond'!V24/'Alice Raymond'!V26 | T3: ='Alice Raymond'!W24/'Alice Raymond'!W26 | U3: ='Alice Raymond'!X24/'Alice Raymond'!X26 | V3: ='Alice Raymond'!Y24/'Alice Raymond'!Y26 | W3: ='Alice Raymond'!Z24/'Alice Raymond'!Z26 | ... Z3: ='Alice Raymond'!AC24/'Alice Raymond'!AC26 | AB3: ='Alice Raymond'!AE24/'Alice Raymond'!AE26
A4: Alvise Axel | B4: ='Alvise Axel'!E24/'Alvise Axel'!E26 | C4: ='Alvise Axel'!F24/'Alvise Axel'!F26 | D4: ='Alvise Axel'!G24/'Alvise Axel'!G26 | E4: ='Alvise Axel'!H24/'Alvise Axel'!H26 | F4: ='Alvise Axel'!I24/'Alvise Axel'!I26 | G4: ='Alvise Axel'!J24/'Alvise Axel'!J26 | H4: ='Alvise Axel'!K24/'Alvise Axel'!K26 | I4: ='Alvise Axel'!L24/'Alvise Axel'!L26 | ... S4: ='Alvise Axel'!V24/'Alvise Axel'!V26 | V4: ='Alvise Axel'!Y24/'Alvise Axel'!Y26 | W4: ='Alvise Axel'!Z24/'Alvise Axel'!Z26 | X4: ='Alvise Axel'!AA24/'Alvise Axel'!AA26 | Y4: ='Alvise Axel'!AB24/'Alvise Axel'!AB26 | Z4: ='Alvise Axel'!AC24/'Alvise Axel'!AC26 | AB4: ='Alvise Axel'!AE24/'Alvise Axel'!AE26
A5: Anthony Kaleb | B5: ='Anthony Kaleb'!E24/'Anthony Kaleb'!E26 | C5: ='Anthony Kaleb'!F24/'Anthony Kaleb'!F26 | E5: ='Anthony Kaleb'!H24/'Anthony Kaleb'!H26 | F5: ='Anthony Kaleb'!I24/'Anthony Kaleb'!I26 | H5: ='Anthony Kaleb'!K24/'Anthony Kaleb'!K26 | I5: ='Anthony Kaleb'!L24/'Anthony Kaleb'!L26 | J5: ='Anthony Kaleb'!M24/'Anthony Kaleb'!M26 | K5: ='Anthony Kaleb'!N24/'Anthony Kaleb'!N26 | L5: ='Anthony Kaleb'!O24/'Anthony Kaleb'!O26 | O5: ='Anthony Kaleb'!R24/'Anthony Kaleb'!R26 | P5: ='Anthony Kaleb'!S24/'Anthony Kaleb'!S26 | Q5: ='Anthony Kaleb'!T24/'Anthony Kaleb'!T26 | R5: ='Anthony Kaleb'!U24/'Anthony Kaleb'!U26 | V5: ='Anthony Kaleb'!Y24/'Anthony Kaleb'!Y26 | W5: ='Anthony Kaleb'!Z24/'Anthony Kaleb'!Z26 | X5: ='Anthony Kaleb'!AA24/'Anthony Kaleb'!AA26 | Y5: ='Anthony Kaleb'!AB24/'Anthony Kaleb'!AB26 | Z5: ='Anthony Kaleb'!AC24/'Anthony Kaleb'!AC26 | AB5: ='Anthony Kaleb'!AE24/'Anthony Kaleb'!AE26
A6: Asher Ryder | B6: ='Asher Ryder'!E24/'Asher Ryder'!E26 | C6: ='Asher Ryder'!F24/'Asher Ryder'!F26 | D6: ='Asher Ryder'!G24/'Asher Ryder'!G26 | E6: ='Asher Ryder'!H24/'Asher Ryder'!H26 | F6: ='Asher Ryder'!I24/'Asher Ryder'!I26 | G6: ='Asher Ryder'!J24/'Asher Ryder'!J26 | I6: ='Asher Ryder'!L24/'Asher Ryder'!L26 | R6: ='Asher Ryder'!U24/'Asher Ryder'!U26 | T6: ='Asher Ryder'!W24/'Asher Ryder'!W26 | U6: ='Asher Ryder'!X24/'Asher Ryder'!X26 | V6: ='Asher Ryder'!Y24/'Asher Ryder'!Y26 | W6: ='Asher Ryder'!Z24/'Asher Ryder'!Z26 | X6: ='Asher Ryder'!AA24/'Asher Ryder'!AA26 | Y6: ='Asher Ryder'!AB24/'Asher Ryder'!AB26 | AA6: ='Asher Ryder'!AD24/'Asher Ryder'!AD26 | AB6: ='Asher Ryder'!AE24/'Asher Ryder'!AE26
A7: Ashley Megan | B7: ='Ashley Megan'!E24/'Ashley Megan'!E26 | C7: ='Ashley Megan'!F24/'Ashley Megan'!F26 | D7: ='Ashley Megan'!G24/'Ashley Megan'!G26 | E7: ='Ashley Megan'!H24/'Ashley Megan'!H26 | F7: ='Ashley Megan'!I24/'Ashley Megan'!I26 | H7: ='Ashley Megan'!K24/'Ashley Megan'!K26 | I7: ='Ashley Megan'!L24/'Ashley Megan'!L26 | J7: ='Ashley Megan'!M24/'Ashley Megan'!M26 | K7: ='Ashley Megan'!N24/'Ashley Megan'!N26 | L7: ='Ashley Megan'!O24/'Ashley Megan'!O26 | O7: ='Ashley Megan'!R24/'Ashley Megan'!R26 | P7: ='Ashley Megan'!S24/'Ashley Megan'!S26 | Q7: ='Ashley Megan'!T24/'Ashley Megan'!T26 | R7: ='Ashley Megan'!U24/'Ashley Megan'!U26 | S7: ='Ashley Megan'!V24/'Ashley Megan'!V26 | V7: ='Ashley Megan'!Y24/'Ashley Megan'!Y26 | W7: ='Ashley Megan'!Z24/'Ashley Megan'!Z26 | X7: ='Ashley Megan'!AA24/'Ashley Megan'!AA26 | Y7: ='Ashley Megan'!AB24/'Ashley Megan'!AB26 | Z7: ='Ashley Megan'!AC24/'Ashley Megan'!AC26 | AB7: ='Ashley Megan'!AE24/'Ashley Megan'!AE26
A8: Austen Brody | B8: ='Austen Brody'!E24/'Austen Brody'!E26 | C8: ='Austen Brody'!F24/'Austen Brody'!F26 | F8: ='Austen Brody'!I24/'Austen Brody'!I26 | AB8: ='Austen Brody'!AE24/'Austen Brody'!AE26
A9: Austin Christopher | B9: ='Austin Christopher'!E24/'Austin Christopher'!E26 | C9: ='Austin Christopher'!F24/'Austin Christopher'!F26 | D9: ='Austin Christopher'!G24/'Austin Christopher'!G26 | F9: ='Austin Christopher'!I24/'Austin Christopher'!I26 | H9: ='Austin Christopher'!K24/'Austin Christopher'!K26 | I9: ='Austin Christopher'!L24/'Austin Christopher'!L26 | J9: ='Austin Christopher'!M24/'Austin Christopher'!M26 | K9: ='Austin Christopher'!N24/'Austin Christopher'!N26 | L9: ='Austin Christopher'!O24/'Austin Christopher'!O26 | O9: ='Austin Christopher'!R24/'Austin Christopher'!R26 | P9: ='Austin Christopher'!S24/'Austin Christopher'!S26 | Q9: ='Austin Christopher'!T24/'Austin Christopher'!T26 | S9: ='Austin Christopher'!V24/'Austin Christopher'!V26 | V9: ='Austin Christopher'!Y24/'Austin Christopher'!Y26 | W9: ='Austin Christopher'!Z24/'Austin Christopher'!Z26 | X9: ='Austin Christopher'!AA24/'Austin Christopher'!AA26 | Y9: ='Austin Christopher'!AB24/'Austin Christopher'!AB26 | Z9: ='Austin Christopher'!AC24/'Austin Christopher'!AC26 | AB9: ='Austin Christopher'!AE24/'Austin Christopher'!AE26
A10: Austin Keith | P10: ='Austin Keith'!S24/'Austin Keith'!S26 | AB10: ='Austin Keith'!AE24/'Austin Keith'!AE26
A11: Ayesha Selena | B11: ='Ayesha Selena'!E24/'Ayesha Selena'!E26 | C11: ='Ayesha Selena'!F24/'Ayesha Selena'!F26 | D11: ='Ayesha Selena'!G24/'Ayesha Selena'!G26 | F11: ='Ayesha Selena'!I24/'Ayesha Selena'!I26 | I11: ='Ayesha Selena'!L24/'Ayesha Selena'!L26 | J11: ='Ayesha Selena'!M24/'Ayesha Selena'!M26 | K11: ='Ayesha Selena'!N24/'Ayesha Selena'!N26 | L11: ='Ayesha Selena'!O24/'Ayesha Selena'!O26 | O11: ='Ayesha Selena'!R24/'Ayesha Selena'!R26 | P11: ='Ayesha Selena'!S24/'Ayesha Selena'!S26 | Q11: ='Ayesha Selena'!T24/'Ayesha Selena'!T26 | S11: ='Ayesha Selena'!V24/'Ayesha Selena'!V26 | V11: ='Ayesha Selena'!Y24/'Ayesha Selena'!Y26 | W11: ='Ayesha Selena'!Z24/'Ayesha Selena'!Z26 | X11: ='Ayesha Selena'!AA24/'Ayesha Selena'!AA26 | Y11: ='Ayesha Selena'!AB24/'Ayesha Selena'!AB26 | Z11: ='Ayesha Selena'!AC24/'Ayesha Selena'!AC26 | AB11: ='Ayesha Selena'!AE24/'Ayesha Selena'!AE26
A12: Barry Rabi | B12: ='Barry Rabi'!E24/'Barry Rabi'!E26 | C12: ='Barry Rabi'!F24/'Barry Rabi'!F26 | D12: ='Barry Rabi'!G24/'Barry Rabi'!G26 | E12: ='Barry Rabi'!H24/'Barry Rabi'!H26 | I12: ='Barry Rabi'!L24/'Barry Rabi'!L26 | J12: ='Barry Rabi'!M24/'Barry Rabi'!M26 | K12: ='Barry Rabi'!N24/'Barry Rabi'!N26 | L12: ='Barry Rabi'!O24/'Barry Rabi'!O26 | O12: ='Barry Rabi'!R24/'Barry Rabi'!R26 | P12: ='Barry Rabi'!S24/'Barry Rabi'!S26 | Q12: ='Barry Rabi'!T24/'Barry Rabi'!T26 | R12: ='Barry Rabi'!U24/'Barry Rabi'!U26 | S12: ='Barry Rabi'!V24/'Barry Rabi'!V26 | W12: ='Barry Rabi'!Z24/'Barry Rabi'!Z26 | X12: ='Barry Rabi'!AA24/'Barry Rabi'!AA26 | Y12: ='Barry Rabi'!AB24/'Barry Rabi'!AB26 | Z12: ='Barry Rabi'!AC24/'Barry Rabi'!AC26 | AA12: ='Barry Rabi'!AD24/'Barry Rabi'!AD26 | AB12: ='Barry Rabi'!AE24/'Barry Rabi'!AE26
A13: Belinda Usmon | D13: ='Belinda Usmon'!G24/'Belinda Usmon'!G26 | I13: ='Belinda Usmon'!L24/'Belinda Usmon'!L26 | K13: ='Belinda Usmon'!N24/'Belinda Usmon'!N26 | L13: ='Belinda Usmon'!O24/'Belinda Usmon'!O26 | P13: ='Belinda Usmon'!S24/'Belinda Usmon'!S26 | Q13: ='Belinda Usmon'!T24/'Belinda Usmon'!T26 | R13: ='Belinda Usmon'!U24/'Belinda Usmon'!U26 | V13: ='Belinda Usmon'!Y24/'Belinda Usmon'!Y26 | W13: ='Belinda Usmon'!Z24/'Belinda Usmon'!Z26 | X13: ='Belinda Usmon'!AA24/'Belinda Usmon'!AA26 | Y13: ='Belinda Usmon'!AB24/'Belinda Usmon'!AB26 | Z13: ='Belinda Usmon'!AC24/'Belinda Usmon'!AC26 | AB13: ='Belinda Usmon'!AE24/'Belinda Usmon'!AE26
A14: Benjamin Ralph | B14: ='Benjamin Ralph'!E24/'Benjamin Ralph'!E26 | C14: ='Benjamin Ralph'!F24/'Benjamin Ralph'!F26 | D14: ='Benjamin Ralph'!G24/'Benjamin Ralph'!G26 | E14: ='Benjamin Ralph'!H24/'Benjamin Ralph'!H26 | F14: ='Benjamin Ralph'!I24/'Benjamin Ralph'!I26 | H14: ='Benjamin Ralph'!K24/'Benjamin Ralph'!K26 | J14: ='Benjamin Ralph'!M24/'Benjamin Ralph'!M26 | K14: ='Benjamin Ralph'!N24/'Benjamin Ralph'!N26 | L14: ='Benjamin Ralph'!O24/'Benjamin Ralph'!O26 | O14: ='Benjamin Ralph'!R24/'Benjamin Ralph'!R26 | P14: ='Benjamin Ralph'!S24/'Benjamin Ralph'!S26 | Q14: ='Benjamin Ralph'!T24/'Benjamin Ralph'!T26 | R14: ='Benjamin Ralph'!U24/'Benjamin Ralph'!U26 | S14: ='Benjamin Ralph'!V24/'Benjamin Ralph'!V26 | V14: ='Benjamin Ralph'!Y24/'Benjamin Ralph'!Y26 | W14: ='Benjamin Ralph'!Z24/'Benjamin Ralph'!Z26 | X14: ='Benjamin Ralph'!AA24/'Benjamin Ralph'!AA26 | Y14: ='Benjamin Ralph'!AB24/'Benjamin Ralph'!AB26 | Z14: ='Benjamin Ralph'!AC24/'Benjamin Ralph'!AC26 | AB14: ='Benjamin Ralph'!AE24/'Benjamin Ralph'!AE26
A15: Beverly Ruwan | B15: ='Beverly Ruwan'!E24/'Beverly Ruwan'!E26 | C15: ='Beverly Ruwan'!F24/'Beverly Ruwan'!F26 | D15: ='Beverly Ruwan'!G24/'Beverly Ruwan'!G26 | H15: ='Beverly Ruwan'!K24/'Beverly Ruwan'!K26 | I15: ='Beverly Ruwan'!L24/'Beverly Ruwan'!L26 | J15: ='Beverly Ruwan'!M24/'Beverly Ruwan'!M26 | K15: ='Beverly Ruwan'!N24/'Beverly Ruwan'!N26 | L15: ='Beverly Ruwan'!O24/'Beverly Ruwan'!O26 | O15: ='Beverly Ruwan'!R24/'Beverly Ruwan'!R26 | P15: ='Beverly Ruwan'!S24/'Beverly Ruwan'!S26 | Q15: ='Beverly Ruwan'!T24/'Beverly Ruwan'!T26 | X15: ='Beverly Ruwan'!AA24/'Beverly Ruwan'!AA26 | Y15: ='Beverly Ruwan'!AB24/'Beverly Ruwan'!AB26 | Z15: ='Beverly Ruwan'!AC24/'Beverly Ruwan'!AC26 | AB15: ='Beverly Ruwan'!AE24/'Beverly Ruwan'!AE26
A16: Bianca Allison | C16: ='Bianca Allison'!F24/'Bianca Allison'!F26 | D16: ='Bianca Allison'!G24/'Bianca Allison'!G26 | H16: ='Bianca Allison'!K24/'Bianca Allison'!K26 | I16: ='Bianca Allison'!L24/'Bianca Allison'!L26 | J16: ='Bianca Allison'!M24/'Bianca Allison'!M26 | K16: ='Bianca Allison'!N24/'Bianca Allison'!N26 | L16: ='Bianca Allison'!O24/'Bianca Allison'!O26 | O16: ='Bianca Allison'!R24/'Bianca Allison'!R26 | P16: ='Bianca Allison'!S24/'Bianca Allison'!S26 | Q16: ='Bianca Allison'!T24/'Bianca Allison'!T26 | S16: ='Bianca Allison'!V24/'Bianca Allison'!V26 | V16: ='Bianca Allison'!Y24/'Bianca Allison'!Y26 | W16: ='Bianca Allison'!Z24/'Bianca Allison'!Z26 | X16: ='Bianca Allison'!AA24/'Bianca Allison'!AA26 | Y16: ='Bianca Allison'!AB24/'Bianca Allison'!AB26 | AB16: ='Bianca Allison'!AE24/'Bianca Allison'!AE26
A17: Brenda Saylor | B17: ='Brenda Saylor'!E24/'Brenda Saylor'!E26 | C17: ='Brenda Saylor'!F24/'Brenda Saylor'!F26 | D17: ='Brenda Saylor'!G24/'Brenda Saylor'!G26 | E17: ='Brenda Saylor'!H24/'Brenda Saylor'!H26 | F17: ='Brenda Saylor'!I24/'Brenda Saylor'!I26 | H17: ='Brenda Saylor'!K24/'Brenda Saylor'!K26 | I17: ='Brenda Saylor'!L24/'Brenda Saylor'!L26 | J17: ='Brenda Saylor'!M24/'Brenda Saylor'!M26 | K17: ='Brenda Saylor'!N24/'Brenda Saylor'!N26 | L17: ='Brenda Saylor'!O24/'Brenda Saylor'!O26 | O17: ='Brenda Saylor'!R24/'Brenda Saylor'!R26 | P17: ='Brenda Saylor'!S24/'Brenda Saylor'!S26 | Q17: ='Brenda Saylor'!T24/'Brenda Saylor'!T26 | R17: ='Brenda Saylor'!U24/'Brenda Saylor'!U26 | S17: ='Brenda Saylor'!V24/'Brenda Saylor'!V26 | T17: ='Brenda Saylor'!W24/'Brenda Saylor'!W26 | U17: ='Brenda Saylor'!X24/'Brenda Saylor'!X26 | V17: ='Brenda Saylor'!Y24/'Brenda Saylor'!Y26 | ... Z17: ='Brenda Saylor'!AC24/'Brenda Saylor'!AC26 | AB17: ='Brenda Saylor'!AE24/'Brenda Saylor'!AE26
A18: Brooklyn Georgia | G18: ='Brooklyn Georgia'!J24/'Brooklyn Georgia'!J26 | H18: ='Brooklyn Georgia'!K24/'Brooklyn Georgia'!K26 | I18: ='Brooklyn Georgia'!L24/'Brooklyn Georgia'!L26 | J18: ='Brooklyn Georgia'!M24/'Brooklyn Georgia'!M26 | K18: ='Brooklyn Georgia'!N24/'Brooklyn Georgia'!N26 | L18: ='Brooklyn Georgia'!O24/'Brooklyn Georgia'!O26 | M18: ='Brooklyn Georgia'!P24/'Brooklyn Georgia'!P26 | N18: ='Brooklyn Georgia'!Q24/'Brooklyn Georgia'!Q26 | ... S18: ='Brooklyn Georgia'!V24/'Brooklyn Georgia'!V26 | V18: ='Brooklyn Georgia'!Y24/'Brooklyn Georgia'!Y26 | W18: ='Brooklyn Georgia'!Z24/'Brooklyn Georgia'!Z26 | X18: ='Brooklyn Georgia'!AA24/'Brooklyn Georgia'!AA26 | Z18: ='Brooklyn Georgia'!AC24/'Brooklyn Georgia'!AC26 | AB18: ='Brooklyn Georgia'!AE24/'Brooklyn Georgia'!AE26
A19: Bryan Vince | B19: ='Bryan Vince'!E24/'Bryan Vince'!E26 | C19: ='Bryan Vince'!F24/'Bryan Vince'!F26 | D19: ='Bryan Vince'!G24/'Bryan Vince'!G26 | E19: ='Bryan Vince'!H24/'Bryan Vince'!H26 | F19: ='Bryan Vince'!I24/'Bryan Vince'!I26 | H19: ='Bryan Vince'!K24/'Bryan Vince'!K26 | I19: ='Bryan Vince'!L24/'Bryan Vince'!L26 | J19: ='Bryan Vince'!M24/'Bryan Vince'!M26 | K19: ='Bryan Vince'!N24/'Bryan Vince'!N26 | L19: ='Bryan Vince'!O24/'Bryan Vince'!O26 | O19: ='Bryan Vince'!R24/'Bryan Vince'!R26 | P19: ='Bryan Vince'!S24/'Bryan Vince'!S26 | R19: ='Bryan Vince'!U24/'Bryan Vince'!U26 | S19: ='Bryan Vince'!V24/'Bryan Vince'!V26 | V19: ='Bryan Vince'!Y24/'Bryan Vince'!Y26 | W19: ='Bryan Vince'!Z24/'Bryan Vince'!Z26 | X19: ='Bryan Vince'!AA24/'Bryan Vince'!AA26 | Y19: ='Bryan Vince'!AB24/'Bryan Vince'!AB26 | Z19: ='Bryan Vince'!AC24/'Bryan Vince'!AC26 | AB19: ='Bryan Vince'!AE24/'Bryan Vince'!AE26
A20: Dane Patrick | C20: ='Dane Patrick'!F24/'Dane Patrick'!F26 | D20: ='Dane Patrick'!G24/'Dane Patrick'!G26 | AB20: ='Dane Patrick'!AE24/'Dane Patrick'!AE26
A21: Della Lily | C21: ='Della Lily'!F24/'Della Lily'!F26 | D21: ='Della Lily'!G24/'Della Lily'!G26 | F21: ='Della Lily'!I24/'Della Lily'!I26 | O21: ='Della Lily'!R24/'Della Lily'!R26 | R21: ='Della Lily'!U24/'Della Lily'!U26 | U21: ='Della Lily'!X24/'Della Lily'!X26 | V21: ='Della Lily'!Y24/'Della Lily'!Y26 | W21: ='Della Lily'!Z24/'Della Lily'!Z26 | X21: ='Della Lily'!AA24/'Della Lily'!AA26 | Y21: ='Della Lily'!AB24/'Della Lily'!AB26 | Z21: ='Della Lily'!AC24/'Della Lily'!AC26 | AB21: ='Della Lily'!AE24/'Della Lily'!AE26
A22: Diana Pamela | B22: ='Diana Pamela'!E24/'Diana Pamela'!E26 | C22: ='Diana Pamela'!F24/'Diana Pamela'!F26 | D22: ='Diana Pamela'!G24/'Diana Pamela'!G26 | H22: ='Diana Pamela'!K24/'Diana Pamela'!K26 | I22: ='Diana Pamela'!L24/'Diana Pamela'!L26 | J22: ='Diana Pamela'!M24/'Diana Pamela'!M26 | K22: ='Diana Pamela'!N24/'Diana Pamela'!N26 | L22: ='Diana Pamela'!O24/'Diana Pamela'!O26 | O22: ='Diana Pamela'!R24/'Diana Pamela'!R26 | P22: ='Diana Pamela'!S24/'Diana Pamela'!S26 | Q22: ='Diana Pamela'!T24/'Diana Pamela'!T26 | R22: ='Diana Pamela'!U24/'Diana Pamela'!U26 | S22: ='Diana Pamela'!V24/'Diana Pamela'!V26 | V22: ='Diana Pamela'!Y24/'Diana Pamela'!Y26 | W22: ='Diana Pamela'!Z24/'Diana Pamela'!Z26 | X22: ='Diana Pamela'!AA24/'Diana Pamela'!AA26 | Y22: ='Diana Pamela'!AB24/'Diana Pamela'!AB26 | Z22: ='Diana Pamela'!AC24/'Diana Pamela'!AC26 | AB22: ='Diana Pamela'!AE24/'Diana Pamela'!AE26
A23: Donald Roman | B23: ='Donald Roman'!E24/'Donald Roman'!E26 | C23: ='Donald Roman'!F24/'Donald Roman'!F26 | D23: ='Donald Roman'!G24/'Donald Roman'!G26 | E23: ='Donald Roman'!H24/'Donald Roman'!H26 | F23: ='Donald Roman'!I24/'Donald Roman'!I26 | H23: ='Donald Roman'!K24/'Donald Roman'!K26 | I23: ='Donald Roman'!L24/'Donald Roman'!L26 | J23: ='Donald Roman'!M24/'Donald Roman'!M26 | K23: ='Donald Roman'!N24/'Donald Roman'!N26 | L23: ='Donald Roman'!O24/'Donald Roman'!O26 | O23: ='Donald Roman'!R24/'Donald Roman'!R26 | P23: ='Donald Roman'!S24/'Donald Roman'!S26 | Q23: ='Donald Roman'!T24/'Donald Roman'!T26 | R23: ='Donald Roman'!U24/'Donald Roman'!U26 | V23: ='Donald Roman'!Y24/'Donald Roman'!Y26 | W23: ='Donald Roman'!Z24/'Donald Roman'!Z26 | X23: ='Donald Roman'!AA24/'Donald Roman'!AA26 | Y23: ='Donald Roman'!AB24/'Donald Roman'!AB26 | Z23: ='Donald Roman'!AC24/'Donald Roman'!AC26 | AB23: ='Donald Roman'!AE24/'Donald Roman'!AE26
A24: Dora Ross | C24: ='Dora Ross'!F24/'Dora Ross'!F26 | D24: ='Dora Ross'!G24/'Dora Ross'!G26 | F24: ='Dora Ross'!I24/'Dora Ross'!I26 | H24: ='Dora Ross'!K24/'Dora Ross'!K26 | I24: ='Dora Ross'!L24/'Dora Ross'!L26 | J24: ='Dora Ross'!M24/'Dora Ross'!M26 | K24: ='Dora Ross'!N24/'Dora Ross'!N26 | L24: ='Dora Ross'!O24/'Dora Ross'!O26 | O24: ='Dora Ross'!R24/'Dora Ross'!R26 | P24: ='Dora Ross'!S24/'Dora Ross'!S26 | R24: ='Dora Ross'!U24/'Dora Ross'!U26 | S24: ='Dora Ross'!V24/'Dora Ross'!V26 | V24: ='Dora Ross'!Y24/'Dora Ross'!Y26 | W24: ='Dora Ross'!Z24/'Dora Ross'!Z26 | X24: ='Dora Ross'!AA24/'Dora Ross'!AA26 | Y24: ='Dora Ross'!AB24/'Dora Ross'!AB26 | Z24: ='Dora Ross'!AC24/'Dora Ross'!AC26 | AB24: ='Dora Ross'!AE24/'Dora Ross'!AE26
A25: Edwin Robert | B25: ='Edwin Robert'!E24/'Edwin Robert'!E26 | I25: ='Edwin Robert'!L24/'Edwin Robert'!L26 | S25: ='Edwin Robert'!V24/'Edwin Robert'!V26 | W25: ='Edwin Robert'!Z24/'Edwin Robert'!Z26 | X25: ='Edwin Robert'!AA24/'Edwin Robert'!AA26 | Y25: ='Edwin Robert'!AB24/'Edwin Robert'!AB26 | Z25: ='Edwin Robert'!AC24/'Edwin Robert'!AC26 | AB25: ='Edwin Robert'!AE24/'Edwin Robert'!AE26
A26: George Reece | B26: ='George Reece'!E24/'George Reece'!E26 | C26: ='George Reece'!F24/'George Reece'!F26 | F26: ='George Reece'!I24/'George Reece'!I26 | H26: ='George Reece'!K24/'George Reece'!K26 | I26: ='George Reece'!L24/'George Reece'!L26 | J26: ='George Reece'!M24/'George Reece'!M26 | K26: ='George Reece'!N24/'George Reece'!N26 | L26: ='George Reece'!O24/'George Reece'!O26 | O26: ='George Reece'!R24/'George Reece'!R26 | P26: ='George Reece'!S24/'George Reece'!S26 | S26: ='George Reece'!V24/'George Reece'!V26 | AB26: ='George Reece'!AE24/'George Reece'!AE26
A27: Georgina Karter | B27: ='Georgina Karter'!E24/'Georgina Karter'!E26 | C27: ='Georgina Karter'!F24/'Georgina Karter'!F26 | D27: ='Georgina Karter'!G24/'Georgina Karter'!G26 | F27: ='Georgina Karter'!I24/'Georgina Karter'!I26 | H27: ='Georgina Karter'!K24/'Georgina Karter'!K26 | I27: ='Georgina Karter'!L24/'Georgina Karter'!L26 | J27: ='Georgina Karter'!M24/'Georgina Karter'!M26 | K27: ='Georgina Karter'!N24/'Georgina Karter'!N26 | O27: ='Georgina Karter'!R24/'Georgina Karter'!R26 | P27: ='Georgina Karter'!S24/'Georgina Karter'!S26 | Q27: ='Georgina Karter'!T24/'Georgina Karter'!T26 | R27: ='Georgina Karter'!U24/'Georgina Karter'!U26 | S27: ='Georgina Karter'!V24/'Georgina Karter'!V26 | V27: ='Georgina Karter'!Y24/'Georgina Karter'!Y26 | W27: ='Georgina Karter'!Z24/'Georgina Karter'!Z26 | X27: ='Georgina Karter'!AA24/'Georgina Karter'!AA26 | Y27: ='Georgina Karter'!AB24/'Georgina Karter'!AB26 | Z27: ='Georgina Karter'!AC24/'Georgina Karter'!AC26 | AB27: ='Georgina Karter'!AE24/'Georgina Karter'!AE26
A28: Gina Suzana | B28: ='Gina Suzana'!E24/'Gina Suzana'!E26 | C28: ='Gina Suzana'!F24/'Gina Suzana'!F26 | E28: ='Gina Suzana'!H24/'Gina Suzana'!H26 | H28: ='Gina Suzana'!K24/'Gina Suzana'!K26 | I28: ='Gina Suzana'!L24/'Gina Suzana'!L26 | J28: ='Gina Suzana'!M24/'Gina Suzana'!M26 | K28: ='Gina Suzana'!N24/'Gina Suzana'!N26 | L28: ='Gina Suzana'!O24/'Gina Suzana'!O26 | O28: ='Gina Suzana'!R24/'Gina Suzana'!R26 | P28: ='Gina Suzana'!S24/'Gina Suzana'!S26 | Q28: ='Gina Suzana'!T24/'Gina Suzana'!T26 | R28: ='Gina Suzana'!U24/'Gina Suzana'!U26 | V28: ='Gina Suzana'!Y24/'Gina Suzana'!Y26 | W28: ='Gina Suzana'!Z24/'Gina Suzana'!Z26 | X28: ='Gina Suzana'!AA24/'Gina Suzana'!AA26 | Y28: ='Gina Suzana'!AB24/'Gina Suzana'!AB26 | Z28: ='Gina Suzana'!AC24/'Gina Suzana'!AC26 | AB28: ='Gina Suzana'!AE24/'Gina Suzana'!AE26
A29: Gloria Edison | E29: ='Gloria Edison'!H24/'Gloria Edison'!H26 | F29: ='Gloria Edison'!I24/'Gloria Edison'!I26 | H29: ='Gloria Edison'!K24/'Gloria Edison'!K26 | I29: ='Gloria Edison'!L24/'Gloria Edison'!L26 | J29: ='Gloria Edison'!M24/'Gloria Edison'!M26 | K29: ='Gloria Edison'!N24/'Gloria Edison'!N26 | L29: ='Gloria Edison'!O24/'Gloria Edison'!O26 | O29: ='Gloria Edison'!R24/'Gloria Edison'!R26 | P29: ='Gloria Edison'!S24/'Gloria Edison'!S26 | R29: ='Gloria Edison'!U24/'Gloria Edison'!U26 | S29: ='Gloria Edison'!V24/'Gloria Edison'!V26 | V29: ='Gloria Edison'!Y24/'Gloria Edison'!Y26 | W29: ='Gloria Edison'!Z24/'Gloria Edison'!Z26 | X29: ='Gloria Edison'!AA24/'Gloria Edison'!AA26 | Y29: ='Gloria Edison'!AB24/'Gloria Edison'!AB26 | AB29: ='Gloria Edison'!AE24/'Gloria Edison'!AE26
A30: Iris Nova | B30: ='Iris Nova'!E24/'Iris Nova'!E26 | C30: ='Iris Nova'!F24/'Iris Nova'!F26 | E30: ='Iris Nova'!H24/'Iris Nova'!H26 | F30: ='Iris Nova'!I24/'Iris Nova'!I26 | H30: ='Iris Nova'!K24/'Iris Nova'!K26 | I30: ='Iris Nova'!L24/'Iris Nova'!L26 | O30: ='Iris Nova'!R24/'Iris Nova'!R26 | P30: ='Iris Nova'!S24/'Iris Nova'!S26 | Q30: ='Iris Nova'!T24/'Iris Nova'!T26 | R30: ='Iris Nova'!U24/'Iris Nova'!U26 | S30: ='Iris Nova'!V24/'Iris Nova'!V26 | V30: ='Iris Nova'!Y24/'Iris Nova'!Y26 | W30: ='Iris Nova'!Z24/'Iris Nova'!Z26 | X30: ='Iris Nova'!AA24/'Iris Nova'!AA26 | Y30: ='Iris Nova'!AB24/'Iris Nova'!AB26 | Z30: ='Iris Nova'!AC24/'Iris Nova'!AC26 | AB30: ='Iris Nova'!AE24/'Iris Nova'!AE26
A31: Irvin Kim | B31: ='Irvin Kim'!E24/'Irvin Kim'!E26 | C31: ='Irvin Kim'!F24/'Irvin Kim'!F26 | D31: ='Irvin Kim'!G24/'Irvin Kim'!G26 | E31: ='Irvin Kim'!H24/'Irvin Kim'!H26 | F31: ='Irvin Kim'!I24/'Irvin Kim'!I26 | H31: ='Irvin Kim'!K24/'Irvin Kim'!K26 | J31: ='Irvin Kim'!M24/'Irvin Kim'!M26 | K31: ='Irvin Kim'!N24/'Irvin Kim'!N26 | L31: ='Irvin Kim'!O24/'Irvin Kim'!O26 | O31: ='Irvin Kim'!R24/'Irvin Kim'!R26 | P31: ='Irvin Kim'!S24/'Irvin Kim'!S26 | Q31: ='Irvin Kim'!T24/'Irvin Kim'!T26 | R31: ='Irvin Kim'!U24/'Irvin Kim'!U26 | S31: ='Irvin Kim'!V24/'Irvin Kim'!V26 | V31: ='Irvin Kim'!Y24/'Irvin Kim'!Y26 | W31: ='Irvin Kim'!Z24/'Irvin Kim'!Z26 | X31: ='Irvin Kim'!AA24/'Irvin Kim'!AA26 | Y31: ='Irvin Kim'!AB24/'Irvin Kim'!AB26 | Z31: ='Irvin Kim'!AC24/'Irvin Kim'!AC26 | AB31: ='Irvin Kim'!AE24/'Irvin Kim'!AE26
A32: Iverson Karter | B32: ='Iverson Karter'!E24/'Iverson Karter'!E26 | E32: ='Iverson Karter'!H24/'Iverson Karter'!H26 | F32: ='Iverson Karter'!I24/'Iverson Karter'!I26 | H32: ='Iverson Karter'!K24/'Iverson Karter'!K26 | I32: ='Iverson Karter'!L24/'Iverson Karter'!L26 | J32: ='Iverson Karter'!M24/'Iverson Karter'!M26 | K32: ='Iverson Karter'!N24/'Iverson Karter'!N26 | L32: ='Iverson Karter'!O24/'Iverson Karter'!O26 | O32: ='Iverson Karter'!R24/'Iverson Karter'!R26 | P32: ='Iverson Karter'!S24/'Iverson Karter'!S26 | Q32: ='Iverson Karter'!T24/'Iverson Karter'!T26 | R32: ='Iverson Karter'!U24/'Iverson Karter'!U26 | S32: ='Iverson Karter'!V24/'Iverson Karter'!V26 | T32: ='Iverson Karter'!W24/'Iverson Karter'!W26 | U32: ='Iverson Karter'!X24/'Iverson Karter'!X26 | V32: ='Iverson Karter'!Y24/'Iverson Karter'!Y26 | ... Z32: ='Iverson Karter'!AC24/'Iverson Karter'!AC26 | AB32: ='Iverson Karter'!AE24/'Iverson Karter'!AE26
A33: Jacob Stev | C33: ='Jacob Stev'!F24/'Jacob Stev'!F26 | D33: ='Jacob Stev'!G24/'Jacob Stev'!G26 | H33: ='Jacob Stev'!K24/'Jacob Stev'!K26 | I33: ='Jacob Stev'!L24/'Jacob Stev'!L26 | J33: ='Jacob Stev'!M24/'Jacob Stev'!M26 | K33: ='Jacob Stev'!N24/'Jacob Stev'!N26 | P33: ='Jacob Stev'!S24/'Jacob Stev'!S26 | Q33: ='Jacob Stev'!T24/'Jacob Stev'!T26 | W33: ='Jacob Stev'!Z24/'Jacob Stev'!Z26 | X33: ='Jacob Stev'!AA24/'Jacob Stev'!AA26 | Y33: ='Jacob Stev'!AB24/'Jacob Stev'!AB26 | Z33: ='Jacob Stev'!AC24/'Jacob Stev'!AC26 | AB33: ='Jacob Stev'!AE24/'Jacob Stev'!AE26
A34: Julianne Moore | B34: ='Julianne Moore'!E24/'Julianne Moore'!E26 | C34: ='Julianne Moore'!F24/'Julianne Moore'!F26 | D34: ='Julianne Moore'!G24/'Julianne Moore'!G26 | H34: ='Julianne Moore'!K24/'Julianne Moore'!K26 | I34: ='Julianne Moore'!L24/'Julianne Moore'!L26 | J34: ='Julianne Moore'!M24/'Julianne Moore'!M26 | O34: ='Julianne Moore'!R24/'Julianne Moore'!R26 | Q34: ='Julianne Moore'!T24/'Julianne Moore'!T26 | V34: ='Julianne Moore'!Y24/'Julianne Moore'!Y26 | W34: ='Julianne Moore'!Z24/'Julianne Moore'!Z26 | X34: ='Julianne Moore'!AA24/'Julianne Moore'!AA26 | Y34: ='Julianne Moore'!AB24/'Julianne Moore'!AB26 | Z34: ='Julianne Moore'!AC24/'Julianne Moore'!AC26 | AB34: ='Julianne Moore'!AE24/'Julianne Moore'!AE26
A35: Kaizen Kane | B35: ='Kaizen Kane'!E24/'Kaizen Kane'!E26 | C35: ='Kaizen Kane'!F24/'Kaizen Kane'!F26 | D35: ='Kaizen Kane'!G24/'Kaizen Kane'!G26 | E35: ='Kaizen Kane'!H24/'Kaizen Kane'!H26 | F35: ='Kaizen Kane'!I24/'Kaizen Kane'!I26 | K35: ='Kaizen Kane'!N24/'Kaizen Kane'!N26 | L35: ='Kaizen Kane'!O24/'Kaizen Kane'!O26 | O35: ='Kaizen Kane'!R24/'Kaizen Kane'!R26 | P35: ='Kaizen Kane'!S24/'Kaizen Kane'!S26 | Q35: ='Kaizen Kane'!T24/'Kaizen Kane'!T26 | R35: ='Kaizen Kane'!U24/'Kaizen Kane'!U26 | S35: ='Kaizen Kane'!V24/'Kaizen Kane'!V26 | V35: ='Kaizen Kane'!Y24/'Kaizen Kane'!Y26 | W35: ='Kaizen Kane'!Z24/'Kaizen Kane'!Z26 | X35: ='Kaizen Kane'!AA24/'Kaizen Kane'!AA26 | Y35: ='Kaizen Kane'!AB24/'Kaizen Kane'!AB26 | Z35: ='Kaizen Kane'!AC24/'Kaizen Kane'!AC26 | AA35: ='Kaizen Kane'!AD24/'Kaizen Kane'!AD26 | AB35: ='Kaizen Kane'!AE24/'Kaizen Kane'!AE26
A36: Kayla Raymond | D36: ='Kayla Raymond'!G24/'Kayla Raymond'!G26 | E36: ='Kayla Raymond'!H24/'Kayla Raymond'!H26 | F36: ='Kayla Raymond'!I24/'Kayla Raymond'!I26 | H36: ='Kayla Raymond'!K24/'Kayla Raymond'!K26 | I36: ='Kayla Raymond'!L24/'Kayla Raymond'!L26 | J36: ='Kayla Raymond'!M24/'Kayla Raymond'!M26 | K36: ='Kayla Raymond'!N24/'Kayla Raymond'!N26 | L36: ='Kayla Raymond'!O24/'Kayla Raymond'!O26 | O36: ='Kayla Raymond'!R24/'Kayla Raymond'!R26 | Q36: ='Kayla Raymond'!T24/'Kayla Raymond'!T26 | R36: ='Kayla Raymond'!U24/'Kayla Raymond'!U26 | V36: ='Kayla Raymond'!Y24/'Kayla Raymond'!Y26 | W36: ='Kayla Raymond'!Z24/'Kayla Raymond'!Z26 | X36: ='Kayla Raymond'!AA24/'Kayla Raymond'!AA26 | Y36: ='Kayla Raymond'!AB24/'Kayla Raymond'!AB26 | Z36: ='Kayla Raymond'!AC24/'Kayla Raymond'!AC26 | AB36: ='Kayla Raymond'!AE24/'Kayla Raymond'!AE26
A37: Kendall Astor | B37: ='Kendall Astor'!E24/'Kendall Astor'!E26 | C37: ='Kendall Astor'!F24/'Kendall Astor'!F26 | D37: ='Kendall Astor'!G24/'Kendall Astor'!G26 | E37: ='Kendall Astor'!H24/'Kendall Astor'!H26 | F37: ='Kendall Astor'!I24/'Kendall Astor'!I26 | J37: ='Kendall Astor'!M24/'Kendall Astor'!M26 | K37: ='Kendall Astor'!N24/'Kendall Astor'!N26 | L37: ='Kendall Astor'!O24/'Kendall Astor'!O26 | O37: ='Kendall Astor'!R24/'Kendall Astor'!R26 | P37: ='Kendall Astor'!S24/'Kendall Astor'!S26 | Q37: ='Kendall Astor'!T24/'Kendall Astor'!T26 | R37: ='Kendall Astor'!U24/'Kendall Astor'!U26 | S37: ='Kendall Astor'!V24/'Kendall Astor'!V26 | V37: ='Kendall Astor'!Y24/'Kendall Astor'!Y26 | W37: ='Kendall Astor'!Z24/'Kendall Astor'!Z26 | X37: ='Kendall Astor'!AA24/'Kendall Astor'!AA26 | Y37: ='Kendall Astor'!AB24/'Kendall Astor'!AB26 | Z37: ='Kendall Astor'!AC24/'Kendall Astor'!AC26 | AB37: ='Kendall Astor'!AE24/'Kendall Astor'!AE26
A38: Kevin Kingston | D38: ='Kevin Kingston'!G24/'Kevin Kingston'!G26 | F38: ='Kevin Kingston'!I24/'Kevin Kingston'!I26 | H38: ='Kevin Kingston'!K24/'Kevin Kingston'!K26 | I38: ='Kevin Kingston'!L24/'Kevin Kingston'!L26 | K38: ='Kevin Kingston'!N24/'Kevin Kingston'!N26 | W38: ='Kevin Kingston'!Z24/'Kevin Kingston'!Z26 | X38: ='Kevin Kingston'!AA24/'Kevin Kingston'!AA26 | Y38: ='Kevin Kingston'!AB24/'Kevin Kingston'!AB26 | AB38: ='Kevin Kingston'!AE24/'Kevin Kingston'!AE26
A39: Loyal Reese | B39: ='Loyal Reese'!E24/'Loyal Reese'!E26 | C39: ='Loyal Reese'!F24/'Loyal Reese'!F26 | D39: ='Loyal Reese'!G24/'Loyal Reese'!G26 | E39: ='Loyal Reese'!H24/'Loyal Reese'!H26 | F39: ='Loyal Reese'!I24/'Loyal Reese'!I26 | H39: ='Loyal Reese'!K24/'Loyal Reese'!K26 | I39: ='Loyal Reese'!L24/'Loyal Reese'!L26 | J39: ='Loyal Reese'!M24/'Loyal Reese'!M26 | K39: ='Loyal Reese'!N24/'Loyal Reese'!N26 | L39: ='Loyal Reese'!O24/'Loyal Reese'!O26 | Q39: ='Loyal Reese'!T24/'Loyal Reese'!T26 | R39: ='Loyal Reese'!U24/'Loyal Reese'!U26 | S39: ='Loyal Reese'!V24/'Loyal Reese'!V26 | T39: ='Loyal Reese'!W24/'Loyal Reese'!W26 | U39: ='Loyal Reese'!X24/'Loyal Reese'!X26 | V39: ='Loyal Reese'!Y24/'Loyal Reese'!Y26 | W39: ='Loyal Reese'!Z24/'Loyal Reese'!Z26 | X39: ='Loyal Reese'!AA24/'Loyal Reese'!AA26 | ... AB39: ='Loyal Reese'!AE24/'Loyal Reese'!AE26
A40: Lyla Silvester | B40: ='Lyla Silvester'!E24/'Lyla Silvester'!E26 | C40: ='Lyla Silvester'!F24/'Lyla Silvester'!F26 | D40: ='Lyla Silvester'!G24/'Lyla Silvester'!G26 | E40: ='Lyla Silvester'!H24/'Lyla Silvester'!H26 | F40: ='Lyla Silvester'!I24/'Lyla Silvester'!I26 | H40: ='Lyla Silvester'!K24/'Lyla Silvester'!K26 | I40: ='Lyla Silvester'!L24/'Lyla Silvester'!L26 | J40: ='Lyla Silvester'!M24/'Lyla Silvester'!M26 | K40: ='Lyla Silvester'!N24/'Lyla Silvester'!N26 | L40: ='Lyla Silvester'!O24/'Lyla Silvester'!O26 | N40: ='Lyla Silvester'!Q24/'Lyla Silvester'!Q26 | O40: ='Lyla Silvester'!R24/'Lyla Silvester'!R26 | P40: ='Lyla Silvester'!S24/'Lyla Silvester'!S26 | Q40: ='Lyla Silvester'!T24/'Lyla Silvester'!T26 | R40: ='Lyla Silvester'!U24/'Lyla Silvester'!U26 | S40: ='Lyla Silvester'!V24/'Lyla Silvester'!V26 | T40: ='Lyla Silvester'!W24/'Lyla Silvester'!W26 | V40: ='Lyla Silvester'!Y24/'Lyla Silvester'!Y26 | W40: ='Lyla Silvester'!Z24/'Lyla Silvester'!Z26 | X40: ='Lyla Silvester'!AA24/'Lyla Silvester'!AA26 | Y40: ='Lyla Silvester'!AB24/'Lyla Silvester'!AB26 | Z40: ='Lyla Silvester'!AC24/'Lyla Silvester'!AC26 | AB40: ='Lyla Silvester'!AE24/'Lyla Silvester'!AE26
...

Sheet Albert Karson
A1: Process | B1: Per Day Target | C1: Hourly Target | D1: Hours/Day | E1: 02/02 | F1: 02/03 | G1: 02/04 | H1: 02/05 | I1: 02/06 | J1: 02/07 | K1: 02/09 | L1: 02/10 | M1: 02/11 | N1: 02/12 | O1: 02/13 | P1: 02/14 | Q1: 02/15 | R1: 02/16 | S1: 02/17 | T1: 02/18 | U1: 02/19 | V1: 02/20 | W1: 02/21 | X1: 02/22 | Y1: 02/23 | Z1: 02/24 | AA1: 02/25 | AB1: 02/26 | AC1: 02/27 | AD1: 02/28 | AE1: MTD Production
A2: Infinity - Loan Setup - Non-QM | B2: 6 | C2: 1.5 | D2: 9
A3: Infinity - Credit - Non-QM | B3: 5 | C3: 1.8 | D3: 9
A4: Infinity - Compliance - Non-QM | B4: 7 | C4: 1.29 | D4: 9
A5: Infinity - Credit QC - Non-QM | B5: 6 | C5: 1.5 | D5: 9
A6: Infinity - Compliance QC - Non-QM | B6: 13 | C6: 0.69 | D6: 9
A7: Infinity -PreClose Loan Setup | B7: 6 | C7: 1.5 | D7: 9
A8: Infinity -PreClose Credit | B8: 6 | C8: 1.5 | D8: 9
A9: Infinity -PreClose Credit QC | B9: 7 | C9: 1.29 | D9: 9
A10: Infinity - Review | B10: 3 | C10: 3 | D10: 9
A11: Infinity - QC | B11: 4 | C11: 2.25 | D11: 9
A13: Canopy - Credit | B13: 3 | C13: 3 | D13: 9
A14: Canopy - Credit- Deephaven | B14: 2 | C14: 4.5 | D14: 9
A15: Canopy - Compliance | B15: 6 | C15: 1.5 | D15: 9 | E15: 0 | F15: 4 | G15: 1 | H15: 3 | I15: 0 | J15: 0 | K15: 0 | L15: 0 | M15: 0 | N15: 3 | O15: 0 | P15: 0 | Q15: 0 | R15: 0 | S15: 4 | T15: 6 | U15: 2 | V15: 2 | W15: 0 | X15: 0 | Y15: 8 | Z15: 6 | AA15: 5 | AB15: 4 | AC15: 3 | AD15: 0
A16: Agency - Credit QC | B16: 8 | C16: 1.3 | D16: 9
A17: Agency - Compliance QC | B17: 13 | C17: 0.69 | D17: 9
A18: Schwab - Credit | B18: 2.5 | C18: 3.6 | D18: 9
A19: Schwab - Credit QC | B19: 5 | C19: 1.8 | D19: 9
A20: Griffin Pre - Credit | B20: 4 | C20: 2.25 | D20: 9
A21: Conditions - Credit (18) | B21: 25 | C21: 0.36 | D21: 9
A22: Conditions - Compliance (20) | B22: 22.5 | C22: 0.4 | D22: 9
A23: Other | B23: 3 | C23: 3 | D23: 9
A24: Points Per Day | F24: =(F15*C15) | G24: =(G15*C15) | H24: =(H15*C15) | N24: =(N15*C15) | S24: =(S15*C15) | T24: =(T15*C15) | U24: =(U15*C15) | V24: =(V15*C15) | Y24: =(Y15*C15) | Z24: =(Z15*C15) | AA24: =(AA15*C15) | AB24: =(AB15*C15) | AC24: =(AC15*C15) | AE24: =SUM(E24:AD24)
A25: Actual Hours Worked | AE25: =SUM(E25:AD25)
A26: Hours Worked (Adjusted as per day target) | AE26: =SUM(E26:AD26)
A27: Approved PTO | E27: 0 | F27: 0 | G27: 0 | H27: 0 | I27: 0 | J27: 0 | K27: 0 | L27: 0 | M27: 0 | N27: 0 | O27: 0 | P27: 0 | Q27: 0 | R27: 0 | S27: 0 | T27: 0 | U27: 0 | V27: 0 | W27: 0 | X27: 0 | Y27: 0 | Z27: 0 | AA27: 0 | AB27: 0 | AC27: 0 | AD27: 0 | AE27: =SUM(E27:AD27)
A28: Producticity % | AE28: =AE24/AE26
A30: Unproductive Time Explanation
A31: Date | B31: Reason | C31: Hours

Sheet Alice Raymond
A1: Process | B1: Per Day Target | C1: Hourly Target | D1: Hours/Day | E1: 02/02 | F1: 02/03 | G1: 02/04 | H1: 02/05 | I1: 02/06 | J1: 02/07 | K1: 02/09 | L1: 02/10 | M1: 02/11 | N1: 02/12 | O1: 02/13 | P1: 02/14 | Q1: 02/15 | R1: 02/16 | S1: 02/17 | T1: 02/18 | U1: 02/19 | V1: 02/20 | W1: 02/21 | X1: 02/22 | Y1: 02/23 | Z1: 02/24 | AA1: 02/25 | AB1: 02/26 | AC1: 02/27 | AD1: 02/28 | AE1: MTD Production
A2: Infinity - Loan Setup - Non-QM | B2: 6 | C2: 1.5 | D2: 9
A3: Infinity - Credit - Non-QM | B3: 5 | C3: 1.8 | D3: 9
A4: Infinity - Compliance - Non-QM | B4: 7 | C4: 1.29 | D4: 9
A5: Infinity - Credit QC - Non-QM | B5: 6 | C5: 1.5 | D5: 9
A6: Infinity - Compliance QC - Non-QM | B6: 13 | C6: 0.69 | D6: 9
A7: Infinity -PreClose Loan Setup | B7: 6 | C7: 1.5 | D7: 9
A8: Infinity -PreClose Credit | B8: 6 | C8: 1.5 | D8: 9
A9: Infinity -PreClose Credit QC | B9: 7 | C9: 1.29 | D9: 9
A10: Infinity - Review | B10: 3 | C10: 3 | D10: 9
A11: Infinity - QC | B11: 4 | C11: 2.25 | D11: 9
A13: Canopy - Credit | B13: 3 | C13: 3 | D13: 9 | E13: 3 | F13: 4 | G13: 2 | H13: 4 | I13: 3 | J13: 0 | K13: 0 | L13: 4 | M13: 3 | N13: 4 | O13: 4 | P13: 0 | Q13: 0 | R13: 0 | S13: 3 | T13: 3 | U13: 4 | V13: 3 | W13: 3 | X13: 4 | Y13: 3 | Z13: 4 | AA13: 3 | AB13: 4 | AC13: 3 | AD13: 0
A14: Canopy - Credit- Deephaven | B14: 2 | C14: 4.5 | D14: 9
A15: Canopy - Compliance | B15: 6 | C15: 1.5 | D15: 9
A16: Agency - Credit QC | B16: 8 | C16: 1.3 | D16: 9
A17: Agency - Compliance QC | B17: 13 | C17: 0.69 | D17: 9
A18: Schwab - Credit | B18: 2.5 | C18: 3.6 | D18: 9
A19: Schwab - Credit QC | B19: 5 | C19: 1.8 | D19: 9
A20: Griffin Pre - Credit | B20: 4 | C20: 2.25 | D20: 9
A21: Conditions - Credit (18) | B21: 25 | C21: 0.36 | D21: 9
A22: Conditions - Compliance (20) | B22: 22.5 | C22: 0.4 | D22: 9
A23: Other | B23: 3 | C23: 3 | D23: 9
A24: Points Per Day | E24: =(E13*C13) | F24: =(F13*C13) | G24: =(G13*C13) | H24: =(H13*C13) | I24: =(I13*C13) | L24: =(L13*C13) | M24: =(M13*C13) | N24: =(N13*C13) | O24: =(O13*C13) | S24: =(S13*C13) | T24: =(T13*C13) | U24: =(U13*C13) | V24: =(V13*C13) | W24: =(W13*C13) | X24: =(X13*C13) | Y24: =(Y13*C13) | Z24: =(Z13*C13) | AA24: =(AA13*C13) | AB24: =(AB13*C13) | AC24: =(AC13*C13) | AE24: =SUM(E24:AD24)
A25: Actual Hours Worked | AE25: =SUM(E25:AD25)
A26: Hours Worked (Adjusted as per day target) | AE26: =SUM(E26:AD26)
A27: Approved PTO | E27: 0 | F27: 0 | G27: 0 | H27: 0 | I27: 0 | J27: 0 | K27: 0 | L27: 0 | M27: 0 | N27: 0 | O27: 0 | P27: 0 | Q27: 0 | R27: 0 | S27: 0 | T27: 0 | U27: 0 | V27: 0 | W27: 0 | X27: 0 | Y27: 0 | Z27: 0 | AA27: 0 | AB27: 0 | AC27: 0 | AD27: 0 | AE27: =SUM(E27:AD27)
A28: Producticity % | AE28: =AE24/AE26
A30: Unproductive Time Explanation
A31: Date | B31: Reason | C31: Hours

Sheet Alvise Axel
A1: Process | B1: Per Day Target | C1: Hourly Target | D1: Hours/Day | E1: 02/02 | F1: 02/03 | G1: 02/04 | H1: 02/05 | I1: 02/06 | J1: 02/07 | K1: 02/09 | L1: 02/10 | M1: 02/11 | N1: 02/12 | O1: 02/13 | P1: 02/14 | Q1: 02/15 | R1: 02/16 | S1: 02/17 | T1: 02/18 | U1: 02/19 | V1: 02/20 | W1: 02/21 | X1: 02/22 | Y1: 02/23 | Z1: 02/24 | AA1: 02/25 | AB1: 02/26 | AC1: 02/27 | AD1: 02/28 | AE1: MTD Production
A2: Infinity - Loan Setup - Non-QM | B2: 6 | C2: 1.5 | D2: 9
A3: Infinity - Credit - Non-QM | B3: 5 | C3: 1.8 | D3: 9
A4: Infinity - Compliance - Non-QM | B4: 7 | C4: 1.29 | D4: 9
A5: Infinity - Credit QC - Non-QM | B5: 6 | C5: 1.5 | D5: 9
A6: Infinity - Compliance QC - Non-QM | B6: 13 | C6: 0.69 | D6: 9
A7: Infinity -PreClose Loan Setup | B7: 6 | C7: 1.5 | D7: 9
A8: Infinity -PreClose Credit | B8: 6 | C8: 1.5 | D8: 9
A9: Infinity -PreClose Credit QC | B9: 7 | C9: 1.29 | D9: 9
A10: Infinity - Review | B10: 3 | C10: 3 | D10: 9
A11: Infinity - QC | B11: 4 | C11: 2.25 | D11: 9
A13: Canopy - Credit | B13: 3 | C13: 3 | D13: 9 | E13: 4 | F13: 3 | G13: 5 | H13: 3 | I13: 3 | J13: 3 | K13: 4 | L13: 3 | M13: 3 | N13: 4 | O13: 2 | P13: 4 | Q13: 4 | R13: 2 | S13: 4 | T13: 3 | U13: 4 | V13: 3 | W13: 0 | X13: 0 | Y13: 3 | Z13: 4 | AA13: 4 | AB13: 3 | AC13: 2 | AD13: 0
A14: Canopy - Credit- Deephaven | B14: 2 | C14: 4.5 | D14: 9
A15: Canopy - Compliance | B15: 6 | C15: 1.5 | D15: 9
A16: Agency - Credit QC | B16: 8 | C16: 1.3 | D16: 9
A17: Agency - Compliance QC | B17: 13 | C17: 0.69 | D17: 9
A18: Schwab - Credit | B18: 2.5 | C18: 3.6 | D18: 9
A19: Schwab - Credit QC | B19: 5 | C19: 1.8 | D19: 9
A20: Griffin Pre - Credit | B20: 4 | C20: 2.25 | D20: 9
A21: Conditions - Credit (18) | B21: 25 | C21: 0.36 | D21: 9
A22: Conditions - Compliance (20) | B22: 22.5 | C22: 0.4 | D22: 9
A23: Other | B23: 3 | C23: 3 | D23: 9
A24: Points Per Day | E24: =(E13*C13) | F24: =(F13*C13) | G24: =(G13*C13) | H24: =(H13*C13) | I24: =(I13*C13) | J24: =(J13*C13) | K24: =(K13*C13) | L24: =(L13*C13) | M24: =(M13*C13) | N24: =(N13*C13) | O24: =(O13*C13) | P24: =(P13*C13) | Q24: =(Q13*C13) | R24: =(R13*C13) | S24: =(S13*C13) | T24: =(T13*C13) | U24: =(U13*C13) | V24: =(V13*C13) | Y24: =(Y13*C13) | Z24: =(Z13*C13) | AA24: =(AA13*C13) | AB24: =(AB13*C13) | AC24: =(AC13*C13) | AE24: =SUM(E24:AD24)
A25: Actual Hours Worked | AE25: =SUM(E25:AD25)
A26: Hours Worked (Adjusted as per day target) | AE26: =SUM(E26:AD26)
A27: Approved PTO | E27: 0 | F27: 0 | G27: 0 | H27: 0 | I27: 0 | J27: 0 | K27: 0 | L27: 0 | M27: 0 | N27: 0 | O27: 0 | P27: 0 | Q27: 0 | R27: 0 | S27: 0 | T27: 0 | U27: 0 | V27: 0 | W27: 0 | X27: 0 | Y27: 0 | Z27: 0 | AA27: 0 | AB27: 0 | AC27: 0 | AD27: 0 | AE27: =SUM(E27:AD27)
A28: Producticity % | AE28: =AE24/AE26
A30: Unproductive Time Explanation
A31: Date | B31: Reason | C31: Hours

Sheet Anthony Kaleb
A1: Process | B1: Per Day Target | C1: Hourly Target | D1: Hours/Day | E1: 02/02 | F1: 02/03 | G1: 02/04 | H1: 02/05 | I1: 02/06 | J1: 02/07 | K1: 02/09 | L1: 02/10 | M1: 02/11 | N1: 02/12 | O1: 02/13 | P1: 02/14 | Q1: 02/15 | R1: 02/16 | S1: 02/17 | T1: 02/18 | U1: 02/19 | V1: 02/20 | W1: 02/21 | X1: 02/22 | Y1: 02/23 | Z1: 02/24 | AA1: 02/25 | AB1: 02/26 | AC1: 02/27 | AD1: 02/28 | AE1: MTD Production
A2: Infinity - Loan Setup - Non-QM | B2: 6 | C2: 1.5 | D2: 9
A3: Infinity - Credit - Non-QM | B3: 5 | C3: 1.8 | D3: 9
A4: Infinity - Compliance - Non-QM | B4: 7 | C4: 1.29 | D4: 9
A5: Infinity - Credit QC - Non-QM | B5: 6 | C5: 1.5 | D5: 9
A6: Infinity - Compliance QC - Non-QM | B6: 13 | C6: 0.69 | D6: 9 | E6: 4 | F6: 2 | G6: 0 | H6: 1 | I6: 2 | J6: 0 | K6: 1 | L6: 13 | M6: 13 | N6: 20 | O6: 11 | P6: 0 | Q6: 0 | R6: 11 | S6: 2 | T6: 2 | U6: 3 | V6: 0 | W6: 0 | X6: 0 | Y6: 10 | Z6: 13 | AA6: 8 | AB6: 10 | AC6: 2 | AD6: 0
A7: Infinity -PreClose Loan Setup | B7: 6 | C7: 1.5 | D7: 9
A8: Infinity -PreClose Credit | B8: 6 | C8: 1.5 | D8: 9
A9: Infinity -PreClose Credit QC | B9: 7 | C9: 1.29 | D9: 9
A10: Infinity - Review | B10: 3 | C10: 3 | D10: 9
A11: Infinity - QC | B11: 4 | C11: 2.25 | D11: 9
A13: Canopy - Credit | B13: 3 | C13: 3 | D13: 9
A14: Canopy - Credit- Deephaven | B14: 2 | C14: 4.5 | D14: 9
A15: Canopy - Compliance | B15: 6 | C15: 1.5 | D15: 9
A16: Agency - Credit QC | B16: 8 | C16: 1.3 | D16: 9
A17: Agency - Compliance QC | B17: 13 | C17: 0.69 | D17: 9
A18: Schwab - Credit | B18: 2.5 | C18: 3.6 | D18: 9
A19: Schwab - Credit QC | B19: 5 | C19: 1.8 | D19: 9
... A21: Conditions - Credit (18) | B21: 25 | C21: 0.36 | D21: 9
A22: Conditions - Compliance (20) | B22: 22.5 | C22: 0.4 | D22: 9 | E22: 2 | F22: 0 | G22: 0 | H22: 2 | I22: 0 | J22: 0 | K22: 1 | L22: 2 | M22: 3 | N22: 1 | O22: 0 | P22: 0 | Q22: 0 | R22: 2 | S22: 0 | T22: 0 | U22: 0 | V22: 0 | W22: 0 | X22: 0 | Y22: 0 | Z22: 0 | AA22: 0 | AB22: 0 | AC22: 0 | AD22: 0
A23: Other | B23: 3 | C23: 3 | D23: 9
A24: Points Per Day | E24: =(E6*C6)+(E22*C22) | F24: =(F6*C6) | H24: =(H6*C6)+(H22*C22) | I24: =(I6*C6) | K24: =(K6*C6)+(K22*C22) | L24: =(L6*C6)+(L22*C22) | M24: =(M6*C6)+(M22*C22) | N24: =(N6*C6)+(N22*C22) | O24: =(O6*C6) | R24: =(R6*C6)+(R22*C22) | S24: =(S6*C6) | T24: =(T6*C6) | U24: =(U6*C6) | Y24: =(Y6*C6) | Z24: =(Z6*C6) | AA24: =(AA6*C6) | AB24: =(AB6*C6) | AC24: =(AC6*C6) | AE24: =SUM(E24:AD24)
A25: Actual Hours Worked | AE25: =SUM(E25:AD25)
A26: Hours Worked (Adjusted as per day target) | AE26: =SUM(E26:AD26)
A27: Approved PTO | E27: 0 | F27: 0 | G27: 0 | H27: 0 | I27: 0 | J27: 0 | K27: 0 | L27: 0 | M27: 0 | N27: 0 | O27: 0 | P27: 0 | Q27: 0 | R27: 0 | S27: 0 | T27: 0 | U27: 0 | V27: 0 | W27: 0 | X27: 0 | Y27: 0 | Z27: 0 | AA27: 0 | AB27: 0 | AC27: 0 | AD27: 0 | AE27: =SUM(E27:AD27)
A28: Producticity % | AE28: =AE24/AE26
A30: Unproductive Time Explanation
A31: Date | B31: Reason | C31: Hours

Sheet Asher Ryder
A1: Process | B1: Per Day Target | C1: Hourly Target | D1: Hours/Day | E1: 02/02 | F1: 02/03 | G1: 02/04 | H1: 02/05 | I1: 02/06 | J1: 02/07 | K1: 02/09 | L1: 02/10 | M1: 02/11 | N1: 02/12 | O1: 02/13 | P1: 02/14 | Q1: 02/15 | R1: 02/16 | S1: 02/17 | T1: 02/18 | U1: 02/19 | V1: 02/20 | W1: 02/21 | X1: 02/22 | Y1: 02/23 | Z1: 02/24 | AA1: 02/25 | AB1: 02/26 | AC1: 02/27 | AD1: 02/28 | AE1: MTD Production
A2: Infinity - Loan Setup - Non-QM | B2: 6 | C2: 1.5 | D2: 9
A3: Infinity - Credit - Non-QM | B3: 5 | C3: 1.8 | D3: 9
A4: Infinity - Compliance - Non-QM | B4: 7 | C4: 1.29 | D4: 9
A5: Infinity - Credit QC - Non-QM | B5: 6 | C5: 1.5 | D5: 9
A6: Infinity - Compliance QC - Non-QM | B6: 13 | C6: 0.69 | D6: 9
A7: Infinity -PreClose Loan Setup | B7: 6 | C7: 1.5 | D7: 9
A8: Infinity -PreClose Credit | B8: 6 | C8: 1.5 | D8: 9
A9: Infinity -PreClose Credit QC | B9: 7 | C9: 1.29 | D9: 9
A10: Infinity - Review | B10: 3 | C10: 3 | D10: 9
A11: Infinity - QC | B11: 4 | C11: 2.25 | D11: 9
A13: Canopy - Credit | B13: 3 | C13: 3 | D13: 9 | E13: 1 | F13: 2 | G13: 4 | H13: 2 | I13: 3 | J13: 3 | K13: 0 | L13: 1 | M13: 0 | N13: 0 | O13: 0 | P13: 0 | Q13: 0 | R13: 0 | S13: 0 | T13: 0 | U13: 1 | V13: 0 | W13: 4 | X13: 3 | Y13: 1 | Z13: 2 | AA13: 1 | AB13: 2 | AC13: 0 | AD13: 3
A14: Canopy - Credit- Deephaven | B14: 2 | C14: 4.5 | D14: 9
A15: Canopy - Compliance | B15: 6 | C15: 1.5 | D15: 9
A16: Agency - Credit QC | B16: 8 | C16: 1.3 | D16: 9
A17: Agency - Compliance QC | B17: 13 | C17: 0.69 | D17: 9
A18: Schwab - Credit | B18: 2.5 | C18: 3.6 | D18: 9
A19: Schwab - Credit QC | B19: 5 | C19: 1.8 | D19: 9
A20: Griffin Pre - Credit | B20: 4 | C20: 2.25 | D20: 9
A21: Conditions - Credit (18) | B21: 25 | C21: 0.36 | D21: 9
A22: Conditions - Compliance (20) | B22: 22.5 | C22: 0.4 | D22: 9
A23: Other | B23: 3 | C23: 3 | D23: 9
A24: Points Per Day | E24: =(E13*C13) | F24: =(F13*C13) | G24: =(G13*C13) | H24: =(H13*C13) | I24: =(I13*C13) | J24: =(J13*C13) | L24: =(L13*C13) | U24: =(U13*C13) | W24: =(W13*C13) | X24: =(X13*C13) | Y24: =(Y13*C13) | Z24: =(Z13*C13) | AA24: =(AA13*C13) | AB24: =(AB13*C13) | AD24: =(AD13*C13) | AE24: =SUM(E24:AD24)
A25: Actual Hours Worked | AE25: =SUM(E25:AD25)
A26: Hours Worked (Adjusted as per day target) | AE26: =SUM(E26:AD26)
A27: Approved PTO | E27: 0 | F27: 0 | G27: 0 | H27: 0 | I27: 0 | J27: 0 | K27: 0 | L27: 0 | M27: 0 | N27: 0 | O27: 0 | P27: 0 | Q27: 0 | R27: 0 | S27: 0 | T27: 0 | U27: 0 | V27: 0 | W27: 0 | X27: 0 | Y27: 0 | Z27: 0 | AA27: 0 | AB27: 0 | AC27: 0 | AD27: 0 | AE27: =SUM(E27:AD27)
A28: Producticity % | AE28: =AE24/AE26
A30: Unproductive Time Explanation
A31: Date | B31: Reason | C31: Hours

Sheet Ashley Megan
A1: Process | B1: Per Day Target | C1: Hourly Target | D1: Hours/Day | E1: 02/02 | F1: 02/03 | G1: 02/04 | H1: 02/05 | I1: 02/06 | J1: 02/07 | K1: 02/09 | L1: 02/10 | M1: 02/11 | N1: 02/12 | O1: 02/13 | P1: 02/14 | Q1: 02/15 | R1: 02/16 | S1: 02/17 | T1: 02/18 | U1: 02/19 | V1: 02/20 | W1: 02/21 | X1: 02/22 | Y1: 02/23 | Z1: 02/24 | AA1: 02/25 | AB1: 02/26 | AC1: 02/27 | AD1: 02/28 | AE1: MTD Production
A2: Infinity - Loan Setup - Non-QM | B2: 6 | C2: 1.5 | D2: 9
A3: Infinity - Credit - Non-QM | B3: 5 | C3: 1.8 | D3: 9
A4: Infinity - Compliance - Non-QM | B4: 7 | C4: 1.29 | D4: 9
A5: Infinity - Credit QC - Non-QM | B5: 6 | C5: 1.5 | D5: 9
A6: Infinity - Compliance QC - Non-QM | B6: 13 | C6: 0.69 | D6: 9
A7: Infinity -PreClose Loan Setup | B7: 6 | C7: 1.5 | D7: 9
A8: Infinity -PreClose Credit | B8: 6 | C8: 1.5 | D8: 9
A9: Infinity -PreClose Credit QC | B9: 7 | C9: 1.29 | D9: 9
A10: Infinity - Review | B10: 3 | C10: 3 | D10: 9
A11: Infinity - QC | B11: 4 | C11: 2.25 | D11: 9
A13: Canopy - Credit | B13: 3 | C13: 3 | D13: 9 | E13: 3 | F13: 3 | G13: 1 | H13: 3 | I13: 3 | J13: 0 | K13: 2 | L13: 3 | M13: 3 | N13: 3 | O13: 3 | P13: 0 | Q13: 0 | R13: 3 | S13: 4 | T13: 3 | U13: 3 | V13: 3 | W13: 0 | X13: 0 | Y13: 3 | Z13: 3 | AA13: 3 | AB13: 3 | AC13: 3 | AD13: 0
A14: Canopy - Credit- Deephaven | B14: 2 | C14: 4.5 | D14: 9
A15: Canopy - Compliance | B15: 6 | C15: 1.5 | D15: 9
A16: Agency - Credit QC | B16: 8 | C16: 1.3 | D16: 9
A17: Agency - Compliance QC | B17: 13 | C17: 0.69 | D17: 9
A18: Schwab - Credit | B18: 2.5 | C18: 3.6 | D18: 9
A19: Schwab - Credit QC | B19: 5 | C19: 1.8 | D19: 9
A20: Griffin Pre - Credit | B20: 4 | C20: 2.25 | D20: 9
A21: Conditions - Credit (18) | B21: 25 | C21: 0.36 | D21: 9
A22: Conditions - Compliance (20) | B22: 22.5 | C22: 0.4 | D22: 9
A23: Other | B23: 3 | C23: 3 | D23: 9
A24: Points Per Day | E24: =(E13*C13) | F24: =(F13*C13) | G24: =(G13*C13) | H24: =(H13*C13) | I24: =(I13*C13) | K24: =(K13*C13) | L24: =(L13*C13) | M24: =(M13*C13) | N24: =(N13*C13) | O24: =(O13*C13) | R24: =(R13*C13) | S24: =(S13*C13) | T24: =(T13*C13) | U24: =(U13*C13) | V24: =(V13*C13) | Y24: =(Y13*C13) | Z24: =(Z13*C13) | AA24: =(AA13*C13) | AB24: =(AB13*C13) | AC24: =(AC13*C13) | AE24: =SUM(E24:AD24)
A25: Actual Hours Worked | AE25: =SUM(E25:AD25)
A26: Hours Worked (Adjusted as per day target) | AE26: =SUM(E26:AD26)
A27: Approved PTO | E27: 0 | F27: 0 | G27: 0 | H27: 0 | I27: 0 | J27: 0 | K27: 0 | L27: 0 | M27: 0 | N27: 0 | O27: 0 | P27: 0 | Q27: 0 | R27: 0 | S27: 0 | T27: 0 | U27: 0 | V27: 0 | W27: 0 | X27: 0 | Y27: 0 | Z27: 0 | AA27: 0 | AB27: 0 | AC27: 0 | AD27: 0 | AE27: =SUM(E27:AD27)
A28: Producticity % | AE28: =AE24/AE26
A30: Unproductive Time Explanation
A31: Date | B31: Reason | C31: Hours

Sheet Austen Brody
A1: Process | B1: Per Day Target | C1: Hourly Target | D1: Hours/Day | E1: 02/02 | F1: 02/03 | G1: 02/04 | H1: 02/05 | I1: 02/06 | J1: 02/07 | K1: 02/09 | L1: 02/10 | M1: 02/11 | N1: 02/12 | O1: 02/13 | P1: 02/14 | Q1: 02/15 | R1: 02/16 | S1: 02/17 | T1: 02/18 | U1: 02/19 | V1: 02/20 | W1: 02/21 | X1: 02/22 | Y1: 02/23 | Z1: 02/24 | AA1: 02/25 | AB1: 02/26 | AC1: 02/27 | AD1: 02/28 | AE1: MTD Production
A2: Infinity - Loan Setup - Non-QM | B2: 6 | C2: 1.5 | D2: 9
A3: Infinity - Credit - Non-QM | B3: 5 | C3: 1.8 | D3: 9
A4: Infinity - Compliance - Non-QM | B4: 7 | C4: 1.29 | D4: 9 | E4: 3 | F4: 1 | G4: 0 | H4: 0 | I4: 1 | J4: 0 | K4: 0 | L4: 0 | M4: 0 | N4: 0 | O4: 0 | P4: 0 | Q4: 0 | R4: 0 | S4: 0 | T4: 0 | U4: 0 | V4: 0 | W4: 0 | X4: 0 | Y4: 0 | Z4: 0 | AA4: 0 | AB4: 0 | AC4: 0 | AD4: 0
A5: Infinity - Credit QC - Non-QM | B5: 6 | C5: 1.5 | D5: 9
A6: Infinity - Compliance QC - Non-QM | B6: 13 | C6: 0.69 | D6: 9
A7: Infinity -PreClose Loan Setup | B7: 6 | C7: 1.5 | D7: 9
A8: Infinity -PreClose Credit | B8: 6 | C8: 1.5 | D8: 9
A9: Infinity -PreClose Credit QC | B9: 7 | C9: 1.29 | D9: 9
A10: Infinity - Review | B10: 3 | C10: 3 | D10: 9
A11: Infinity - QC | B11: 4 | C11: 2.25 | D11: 9
A13: Canopy - Credit | B13: 3 | C13: 3 | D13: 9
A14: Canopy - Credit- Deephaven | B14: 2 | C14: 4.5 | D14: 9
A15: Canopy - Compliance | B15: 6 | C15: 1.5 | D15: 9
A16: Agency - Credit QC | B16: 8 | C16: 1.3 | D16: 9
A17: Agency - Compliance QC | B17: 13 | C17: 0.69 | D17: 9
... A23: Other | B23: 3 | C23: 3 | D23: 9
A24: Points Per Day | E24: =(E4*C4) | F24: =(F4*C4) | I24: =(I4*C4) | AE24: =SUM(E24:AD24)
A25: Actual Hours Worked | AE25: =SUM(E25:AD25)
A26: Hours Worked (Adjusted as per day target) | AE26: =SUM(E26:AD26)
A27: Approved PTO | E27: 0 | F27: 0 | G27: 0 | H27: 0 | I27: 0 | J27: 0 | K27: 0 | L27: 0 | M27: 0 | N27: 0 | O27: 0 | P27: 0 | Q27: 0 | R27: 0 | S27: 0 | T27: 0 | U27: 0 | V27: 0 | W27: 0 | X27: 0 | Y27: 0 | Z27: 0 | AA27: 0 | AB27: 0 | AC27: 0 | AD27: 0 | AE27: =SUM(E27:AD27)
A28: Producticity % | AE28: =AE24/AE26
A30: Unproductive Time Explanation
A31: Date | B31: Reason | C31: Hours

Sheet Austin Christopher
A1: Process | B1: Per Day Target | C1: Hourly Target | D1: Hours/Day | E1: 02/02 | F1: 02/03 | G1: 02/04 | H1: 02/05 | I1: 02/06 | J1: 02/07 | K1: 02/09 | L1: 02/10 | M1: 02/11 | N1: 02/12 | O1: 02/13 | P1: 02/14 | Q1: 02/15 | R1: 02/16 | S1: 02/17 | T1: 02/18 | U1: 02/19 | V1: 02/20 | W1: 02/21 | X1: 02/22 | Y1: 02/23 | Z1: 02/24 | AA1: 02/25 | AB1: 02/26 | AC1: 02/27 | AD1: 02/28 | AE1: MTD Production
A2: Infinity - Loan Setup - Non-QM | B2: 6 | C2: 1.5 | D2: 9
A3: Infinity - Credit - Non-QM | B3: 5 | C3: 1.8 | D3: 9
A4: Infinity - Compliance - Non-QM | B4: 7 | C4: 1.29 | D4: 9
A5: Infinity - Credit QC - Non-QM | B5: 6 | C5: 1.5 | D5: 9
A6: Infinity - Compliance QC - Non-QM | B6: 13 | C6: 0.69 | D6: 9
A7: Infinity -PreClose Loan Setup | B7: 6 | C7: 1.5 | D7: 9
A8: Infinity -PreClose Credit | B8: 6 | C8: 1.5 | D8: 9
A9: Infinity -PreClose Credit QC | B9: 7 | C9: 1.29 | D9: 9
A10: Infinity - Review | B10: 3 | C10: 3 | D10: 9
A11: Infinity - QC | B11: 4 | C11: 2.25 | D11: 9
A13: Canopy - Credit | B13: 3 | C13: 3 | D13: 9 | E13: 1 | F13: 1 | G13: 1 | H13: 0 | I13: 1 | J13: 0 | K13: 2 | L13: 1 | M13: 1 | N13: 1 | O13: 1 | P13: 0 | Q13: 0 | R13: 1 | S13: 1 | T13: 1 | U13: 0 | V13: 1 | W13: 0 | X13: 0 | Y13: 1 | Z13: 1 | AA13: 1 | AB13: 1 | AC13: 1 | AD13: 0
A14: Canopy - Credit- Deephaven | B14: 2 | C14: 4.5 | D14: 9
A15: Canopy - Compliance | B15: 6 | C15: 1.5 | D15: 9
A16: Agency - Credit QC | B16: 8 | C16: 1.3 | D16: 9
A17: Agency - Compliance QC | B17: 13 | C17: 0.69 | D17: 9
A18: Schwab - Credit | B18: 2.5 | C18: 3.6 | D18: 9
A19: Schwab - Credit QC | B19: 5 | C19: 1.8 | D19: 9
A20: Griffin Pre - Credit | B20: 4 | C20: 2.25 | D20: 9
A21: Conditions - Credit (18) | B21: 25 | C21: 0.36 | D21: 9
A22: Conditions - Compliance (20) | B22: 22.5 | C22: 0.4 | D22: 9
A23: Other | B23: 3 | C23: 3 | D23: 9
A24: Points Per Day | E24: =(E13*C13) | F24: =(F13*C13) | G24: =(G13*C13) | I24: =(I13*C13) | K24: =(K13*C13) | L24: =(L13*C13) | M24: =(M13*C13) | N24: =(N13*C13) | O24: =(O13*C13) | R24: =(R13*C13) | S24: =(S13*C13) | T24: =(T13*C13) | V24: =(V13*C13) | Y24: =(Y13*C13) | Z24: =(Z13*C13) | AA24: =(AA13*C13) | AB24: =(AB13*C13) | AC24: =(AC13*C13) | AE24: =SUM(E24:AD24)
A25: Actual Hours Worked | AE25: =SUM(E25:AD25)
A26: Hours Worked (Adjusted as per day target) | AE26: =SUM(E26:AD26)
A27: Approved PTO | E27: 0 | F27: 0 | G27: 0 | H27: 0 | I27: 0 | J27: 0 | K27: 0 | L27: 0 | M27: 0 | N27: 0 | O27: 0 | P27: 0 | Q27: 0 | R27: 0 | S27: 0 | T27: 0 | U27: 0 | V27: 0 | W27: 0 | X27: 0 | Y27: 0 | Z27: 0 | AA27: 0 | AB27: 0 | AC27: 0 | AD27: 0 | AE27: =SUM(E27:AD27)
A28: Producticity % | AE28: =AE24/AE26
A30: Unproductive Time Explanation
A31: Date | B31: Reason | C31: Hours

Sheet Austin Keith
A1: Process | B1: Per Day Target | C1: Hourly Target | D1: Hours/Day | E1: 02/02 | F1: 02/03 | G1: 02/04 | H1: 02/05 | I1: 02/06 | J1: 02/07 | K1: 02/09 | L1: 02/10 | M1: 02/11 | N1: 02/12 | O1: 02/13 | P1: 02/14 | Q1: 02/15 | R1: 02/16 | S1: 02/17 | T1: 02/18 | U1: 02/19 | V1: 02/20 | W1: 02/21 | X1: 02/22 | Y1: 02/23 | Z1: 02/24 | AA1: 02/25 | AB1: 02/26 | AC1: 02/27 | AD1: 02/28 | AE1: MTD Production
A2: Infinity - Loan Setup - Non-QM | B2: 6 | C2: 1.5 | D2: 9
A3: Infinity - Credit - Non-QM | B3: 5 | C3: 1.8 | D3: 9
A4: Infinity - Compliance - Non-QM | B4: 7 | C4: 1.29 | D4: 9
A5: Infinity - Credit QC - Non-QM | B5: 6 | C5: 1.5 | D5: 9
A6: Infinity - Compliance QC - Non-QM | B6: 13 | C6: 0.69 | D6: 9
A7: Infinity -PreClose Loan Setup | B7: 6 | C7: 1.5 | D7: 9
A8: Infinity -PreClose Credit | B8: 6 | C8: 1.5 | D8: 9
A9: Infinity -PreClose Credit QC | B9: 7 | C9: 1.29 | D9: 9
A10: Infinity - Review | B10: 3 | C10: 3 | D10: 9
A11: Infinity - QC | B11: 4 | C11: 2.25 | D11: 9 | E11: 0 | F11: 0 | G11: 0 | H11: 0 | I11: 0 | J11: 0 | K11: 0 | L11: 0 | M11: 0 | N11: 0 | O11: 0 | P11: 0 | Q11: 0 | R11: 0 | S11: 1 | T11: 0 | U11: 0 | V11: 0 | W11: 0 | X11: 0 | Y11: 0 | Z11: 0 | AA11: 0 | AB11: 0 | AC11: 0 | AD11: 0
A13: Canopy - Credit | B13: 3 | C13: 3 | D13: 9
A14: Canopy - Credit- Deephaven | B14: 2 | C14: 4.5 | D14: 9
A15: Canopy - Compliance | B15: 6 | C15: 1.5 | D15: 9
A16: Agency - Credit QC | B16: 8 | C16: 1.3 | D16: 9
A17: Agency - Compliance QC | B17: 13 | C17: 0.69 | D17: 9
A18: Schwab - Credit | B18: 2.5 | C18: 3.6 | D18: 9
A19: Schwab - Credit QC | B19: 5 | C19: 1.8 | D19: 9
A20: Griffin Pre - Credit | B20: 4 | C20: 2.25 | D20: 9
A21: Conditions - Credit (18) | B21: 25 | C21: 0.36 | D21: 9
A22: Conditions - Compliance (20) | B22: 22.5 | C22: 0.4 | D22: 9
A23: Other | B23: 3 | C23: 3 | D23: 9
A24: Points Per Day | S24: =(S11*C11) | AE24: =SUM(E24:AD24)
A25: Actual Hours Worked | AE25: =SUM(E25:AD25)
A26: Hours Worked (Adjusted as per day target) | AE26: =SUM(E26:AD26)
A27: Approved PTO | E27: 0 | F27: 0 | G27: 0 | H27: 0 | I27: 0 | J27: 0 | K27: 0 | L27: 0 | M27: 0 | N27: 0 | O27: 0 | P27: 0 | Q27: 0 | R27: 0 | S27: 0 | T27: 0 | U27: 0 | V27: 0 | W27: 0 | X27: 0 | Y27: 0 | Z27: 0 | AA27: 0 | AB27: 0 | AC27: 0 | AD27: 0 | AE27: =SUM(E27:AD27)
A28: Producticity % | AE28: =AE24/AE26
A30: Unproductive Time Explanation
A31: Date | B31: Reason | C31: Hours

Sheet Ayesha Selena
A1: Process | B1: Per Day Target | C1: Hourly Target | D1: Hours/Day | E1: 02/02 | F1: 02/03 | G1: 02/04 | H1: 02/05 | I1: 02/06 | J1: 02/07 | K1: 02/09 | L1: 02/10 | M1: 02/11 | N1: 02/12 | O1: 02/13 | P1: 02/14 | Q1: 02/15 | R1: 02/16 | S1: 02/17 | T1: 02/18 | U1: 02/19 | V1: 02/20 | W1: 02/21 | X1: 02/22 | Y1: 02/23 | Z1: 02/24 | AA1: 02/25 | AB1: 02/26 | AC1: 02/27 | AD1: 02/28 | AE1: MTD Production
A2: Infinity - Loan Setup - Non-QM | B2: 6 | C2: 1.5 | D2: 9
A3: Infinity - Credit - Non-QM | B3: 5 | C3: 1.8 | D3: 9 | E3: 0 | F3: 0 | G3: 0 | H3: 0 | I3: 0 | J3: 0 | K3: 0 | L3: 5 | M3: 5 | N3: 5 | O3: 3 | P3: 0 | Q3: 0 | R3: 0 | S3: 1 | T3: 0 | U3: 0 | V3: 0 | W3: 0 | X3: 0 | Y3: 2 | Z3: 4 | AA3: 3 | AB3: 4 | AC3: 3 | AD3: 0
A4: Infinity - Compliance - Non-QM | B4: 7 | C4: 1.29 | D4: 9
A5: Infinity - Credit QC - Non-QM | B5: 6 | C5: 1.5 | D5: 9
A6: Infinity - Compliance QC - Non-QM | B6: 13 | C6: 0.69 | D6: 9
A7: Infinity -PreClose Loan Setup | B7: 6 | C7: 1.5 | D7: 9
A8: Infinity -PreClose Credit | B8: 6 | C8: 1.5 | D8: 9 | E8: 1 | F8: 1 | G8: 1 | H8: 0 | I8: 1 | J8: 0 | K8: 0 | L8: 0 | M8: 0 | N8: 0 | O8: 0 | P8: 0 | Q8: 0 | R8: 1 | S8: 0 | T8: 1 | U8: 0 | V8: 1 | W8: 0 | X8: 0 | Y8: 1 | Z8: 0 | AA8: 1 | AB8: 0 | AC8: 1 | AD8: 0
A9: Infinity -PreClose Credit QC | B9: 7 | C9: 1.29 | D9: 9
A10: Infinity - Review | B10: 3 | C10: 3 | D10: 9
A11: Infinity - QC | B11: 4 | C11: 2.25 | D11: 9
A13: Canopy - Credit | B13: 3 | C13: 3 | D13: 9
A14: Canopy - Credit- Deephaven | B14: 2 | C14: 4.5 | D14: 9
A15: Canopy - Compliance | B15: 6 | C15: 1.5 | D15: 9
A16: Agency - Credit QC | B16: 8 | C16: 1.3 | D16: 9
A17: Agency - Compliance QC | B17: 13 | C17: 0.69 | D17: 9
A18: Schwab - Credit | B18: 2.5 | C18: 3.6 | D18: 9
A19: Schwab - Credit QC | B19: 5 | C19: 1.8 | D19: 9
A20: Griffin Pre - Credit | B20: 4 | C20: 2.25 | D20: 9
A21: Conditions - Credit (18) | B21: 25 | C21: 0.36 | D21: 9
... A23: Other | B23: 3 | C23: 3 | D23: 9
A24: Points Per Day | E24: =(E8*C8) | F24: =(F8*C8) | G24: =(G8*C8) | I24: =(I8*C8) | L24: =(L3*C3) | M24: =(M3*C3) | N24: =(N3*C3) | O24: =(O3*C3) | R24: =(R8*C8) | S24: =(S3*C3) | T24: =(T8*C8) | V24: =(V8*C8) | Y24: =(Y3*C3)+(Y8*C8) | Z24: =(Z3*C3) | AA24: =(AA3*C3)+(AA8*C8) | AB24: =(AB3*C3) | AC24: =(AC3*C3)+(AC8*C8) | AE24: =SUM(E24:AD24)
A25: Actual Hours Worked | AE25: =SUM(E25:AD25)
A26: Hours Worked (Adjusted as per day target) | AE26: =SUM(E26:AD26)
A27: Approved PTO | E27: 0 | F27: 0 | G27: 0 | H27: 0 | I27: 0 | J27: 0 | K27: 0 | L27: 0 | M27: 0 | N27: 0 | O27: 0 | P27: 0 | Q27: 0 | R27: 0 | S27: 0 | T27: 0 | U27: 0 | V27: 0 | W27: 0 | X27: 0 | Y27: 0 | Z27: 0 | AA27: 0 | AB27: 0 | AC27: 0 | AD27: 0 | AE27: =SUM(E27:AD27)
A28: Producticity % | AE28: =AE24/AE26
A30: Unproductive Time Explanation
A31: Date | B31: Reason | C31: Hours

Sheet Barry Rabi
A1: Process | B1: Per Day Target | C1: Hourly Target | D1: Hours/Day | E1: 02/02 | F1: 02/03 | G1: 02/04 | H1: 02/05 | I1: 02/06 | J1: 02/07 | K1: 02/09 | L1: 02/10 | M1: 02/11 | N1: 02/12 | O1: 02/13 | P1: 02/14 | Q1: 02/15 | R1: 02/16 | S1: 02/17 | T1: 02/18 | U1: 02/19 | V1: 02/20 | W1: 02/21 | X1: 02/22 | Y1: 02/23 | Z1: 02/24 | AA1: 02/25 | AB1: 02/26 | AC1: 02/27 | AD1: 02/28 | AE1: MTD Production
A2: Infinity - Loan Setup - Non-QM | B2: 6 | C2: 1.5 | D2: 9
A3: Infinity - Credit - Non-QM | B3: 5 | C3: 1.8 | D3: 9
A4: Infinity - Compliance - Non-QM | B4: 7 | C4: 1.29 | D4: 9
A5: Infinity - Credit QC - Non-QM | B5: 6 | C5: 1.5 | D5: 9 | E5: 0 | F5: 1 | G5: 0 | H5: 0 | I5: 0 | J5: 0 | K5: 0 | L5: 6 | M5: 6 | N5: 7 | O5: 5 | P5: 0 | Q5: 0 | R5: 1 | S5: 1 | T5: 0 | U5: 1 | V5: 0 | W5: 0 | X5: 0 | Y5: 0 | Z5: 5 | AA5: 5 | AB5: 5 | AC5: 4 | AD5: 0
A6: Infinity - Compliance QC - Non-QM | B6: 13 | C6: 0.69 | D6: 9
A7: Infinity -PreClose Loan Setup | B7: 6 | C7: 1.5 | D7: 9
A8: Infinity -PreClose Credit | B8: 6 | C8: 1.5 | D8: 9
A9: Infinity -PreClose Credit QC | B9: 7 | C9: 1.29 | D9: 9 | E9: 1 | F9: 0 | G9: 4 | H9: 1 | I9: 0 | J9: 0 | K9: 0 | L9: 0 | M9: 0 | N9: 0 | O9: 1 | P9: 0 | Q9: 0 | R9: 0 | S9: 0 | T9: 1 | U9: 2 | V9: 1 | W9: 0 | X9: 0 | Y9: 0 | Z9: 1 | AA9: 1 | AB9: 1 | AC9: 2 | AD9: 0
A10: Infinity - Review | B10: 3 | C10: 3 | D10: 9
A11: Infinity - QC | B11: 4 | C11: 2.25 | D11: 9
A13: Canopy - Credit | B13: 3 | C13: 3 | D13: 9 | E13: 0 | F13: 0 | G13: 0 | H13: 0 | I13: 0 | J13: 0 | K13: 0 | L13: 0 | M13: 0 | N13: 0 | O13: 0 | P13: 0 | Q13: 0 | R13: 0 | S13: 0 | T13: 0 | U13: 0 | V13: 0 | W13: 0 | X13: 0 | Y13: 0 | Z13: 0 | AA13: 0 | AB13: 0 | AC13: 0 | AD13: 3
A14: Canopy - Credit- Deephaven | B14: 2 | C14: 4.5 | D14: 9
A15: Canopy - Compliance | B15: 6 | C15: 1.5 | D15: 9
A16: Agency - Credit QC | B16: 8 | C16: 1.3 | D16: 9
A17: Agency - Compliance QC | B17: 13 | C17: 0.69 | D17: 9
A18: Schwab - Credit | B18: 2.5 | C18: 3.6 | D18: 9
A19: Schwab - Credit QC | B19: 5 | C19: 1.8 | D19: 9
A20: Griffin Pre - Credit | B20: 4 | C20: 2.25 | D20: 9
A21: Conditions - Credit (18) | B21: 25 | C21: 0.36 | D21: 9
A22: Conditions - Compliance (20) | B22: 22.5 | C22: 0.4 | D22: 9
A23: Other | B23: 3 | C23: 3 | D23: 9
A24: Points Per Day | E24: =(E9*C9) | F24: =(F5*C5) | G24: =(G9*C9) | H24: =(H9*C9) | L24: =(L5*C5) | M24: =(M5*C5) | N24: =(N5*C5) | O24: =(O5*C5)+(O9*C9) | R24: =(R5*C5) | S24: =(S5*C5) | T24: =(T9*C9) | U24: =(U5*C5)+(U9*C9) | V24: =(V9*C9) | Z24: =(Z5*C5)+(Z9*C9) | AA24: =(AA5*C5)+(AA9*C9) | AB24: =(AB5*C5)+(AB9*C9) | AC24: =(AC5*C5)+(AC9*C9) | AD24: =(AD13*C13) | AE24: =SUM(E24:AD24)
A25: Actual Hours Worked | AE25: =SUM(E25:AD25)
A26: Hours Worked (Adjusted as per day target) | AE26: =SUM(E26:AD26)
A27: Approved PTO | E27: 0 | F27: 0 | G27: 0 | H27: 0 | I27: 0 | J27: 0 | K27: 0 | L27: 0 | M27: 0 | N27: 0 | O27: 0 | P27: 0 | Q27: 0 | R27: 0 | S27: 0 | T27: 0 | U27: 0 | V27: 0 | W27: 0 | X27: 0 | Y27: 0 | Z27: 0 | AA27: 0 | AB27: 0 | AC27: 0 | AD27: 0 | AE27: =SUM(E27:AD27)
A28: Producticity % | AE28: =AE24/AE26
